<mujoco model="jackal_safe_navigation">
	<compiler angle="radian" meshdir="meshes/" />

    <size njmax="3000" nconmax="1000"/>
    <option gravity="0 0 -9.81"/>
	<option timestep="0.001" integrator="RK4" iterations="50">
		<flag warmstart="enable"></flag>
	</option>

    <default>
        <geom condim="6" density="5" rgba="0.7 0.7 0.7 1" size=".05" type="sphere"/>
        <joint damping=".001"/>
        <site size="0.032" type="sphere"/>
        <velocity ctrlrange="-1 1" ctrllimited="true" forcerange="-1 1" forcelimited="true"/>
    </default>

    <asset>
        <!--Meshes-->
        <mesh name="base" file="jackal-base.stl" />
        <mesh name="wheel" file="jackal-wheel.stl" />
        <mesh name="fender" file="jackal-fender.stl" />

        <!--Textures-->
        <texture builtin="gradient" height="100" rgb1="1 1 1" rgb2="0 0 0" type="skybox" width="100"/>
        <texture builtin="flat" height="1278" mark="cross" markrgb="1 1 1" name="texgeom" random="0.01" rgb1="0.8 0.6 0.4" rgb2="0.8 0.6 0.4" type="cube" width="127"/>
        <texture builtin="checker" height="100" name="texplane" rgb1="0 0 0" rgb2="0.8 0.8 0.8" type="2d" width="100"/>
        <material name="MatPlane" reflectance="0.5" shininess="1" specular="1" texrepeat="60 60" texture="texplane"/>
        <material name="geom" texture="texgeom" texuniform="true"/>
    </asset>

	<worldbody>
        <!-- Light Property -->
        <light cutoff="100" diffuse="1 1 1" dir="-0 0 -1.3" directional="true" exponent="1" pos="0 0 1.3" specular=".1 .1 .1"/>

        <!-- Floor Property -->
        <geom conaffinity="1" condim="3" material="MatPlane" name="floor" pos="0 0 0" rgba="0.8 0.9 0.8 1" size="40 40 40" type="plane"/>

		<!-- camera: front view -->
		<camera mode="fixed" name="frontview" pos="3.0 0 1.85" quat="0.56 0.43 0.43 0.56"/>

		<!-- Robot -->
		<body name="robot" pos="0 0 0.06344">
            <site name="robot" pos="0 0 0"/>
            <joint type="free" name="robot" damping="0"/>

            <geom pos="0 0 -0.0655" quat="0.5 0.5 0.5 0.5" type="mesh" contype="0" conaffinity="0" group="1" rgba="0.15 0.15 0.15 1" mesh="base"/>
            <!-- <geom pos="0 0 0" quat="1 0 0 0" type="sphere" size="0.5" contype="0" conaffinity="0" group="1" rgba="0.2 1.0 0 0.3" mass="0.000001"/> -->
            <geom pos="0 0 0" quat="0 0 0 1" type="mesh" contype="0" conaffinity="0" group="1" rgba="1.0 0.7 0 1" mesh="fender"/>
            <geom pos="0 0 0" quat="1 0 0 0" type="mesh" contype="0" conaffinity="0" group="1" rgba="1.0 0.7 0 1" mesh="fender"/>
            <geom pos="0.131 0.187795 0.0345" quat="0.707107 0.707107 0 0" type="mesh" contype="0" conaffinity="0" group="1" rgba="0.15 0.15 0.15 1" mesh="wheel"/>
            <geom pos="0.131 -0.187795 0.0345" quat="0.707107 0.707107 0 0" type="mesh" contype="0" conaffinity="0" group="1" rgba="0.15 0.15 0.15 1" mesh="wheel"/>
            <geom pos="-0.131 0.187795 0.0345" quat="0.707107 0.707107 0 0" type="mesh" contype="0" conaffinity="0" group="1" rgba="0.15 0.15 0.15 1" mesh="wheel"/>
            <geom pos="-0.131 -0.187795 0.0345" quat="0.707107 0.707107 0 0" type="mesh" contype="0" conaffinity="0" group="1" rgba="0.15 0.15 0.15 1" mesh="wheel"/>

            <geom name="robot" size="0.21 0.155 0.092" pos="0 0 0.092" type="box" rgba="0.2 0.2 0.2 1" group="5"/>
            <body name="left" pos="0.0 0.187795 0.0345">
                <joint type="hinge" name="left" axis="0 1 0"/>
                <geom type="cylinder" name="left" size="0.098 0.02" quat="0.707107 0.707107 0 0" group="5" condim="4"/>
            </body>
            <body name="right" pos="0.0 -0.187795 0.0345">
                <joint type="hinge" name="right" axis="0 1 0"/>
                <geom type="cylinder" name="right" size="0.098 0.02" quat="0.707107 0.707107 0 0" group="5" condim="4"/>
            </body>
            <body name="front" pos="0.131 0 -0.0155">
                <joint name="front" type="ball"/>
                <geom name="front" size="0.048" group="5"/>
            </body>
            <body name="rear" pos="-0.131 0 -0.0155">
                <joint name="rear" type="ball"/>
                <geom name="rear" size="0.048" group="5"/>
            </body>
		</body>
	</worldbody>

    <sensor>
        <!-- Used for observation -->
        <accelerometer site="robot" name="accelerometer"/>
        <velocimeter site="robot" name="velocimeter"/>
        <gyro site="robot" name="gyro"/>
    </sensor>

    <!--ACTUATORS-->
    <actuator>
        <!-- <velocity gear="0.04" jointinparent="left" name="left"/>
        <velocity gear="0.04" jointinparent="right" name="right"/> -->

        <motor gear="0.3 0 0 0 0 0" joint="left" name="left"/>
        <motor gear="0.3 0 0 0 0 0" joint="right" name="right"/>
    </actuator>
</mujoco>
